
  0%|                                                                                                                                                                                   | 0/100 [00:00<?, ?it/s]
Traceback (most recent call last):
  File "train_seq2seq.py", line 62, in <module>
    main(args)
  File "train_seq2seq.py", line 45, in main
    train_loss =train(model,train_loader,optimizer,criterion,device)
  File "/mnt/disk1/vaipe-longnd/OCR-prj-deeplearning/src/utils/trainer.py", line 8, in train
    for i in tqdm(dataloader):
  File "/home/aiotlab/anaconda3/envs/longvaipe/lib/python3.8/site-packages/tqdm/std.py", line 1180, in __iter__
    for obj in iterable:
  File "/home/aiotlab/anaconda3/envs/longvaipe/lib/python3.8/site-packages/torch/utils/data/dataloader.py", line 521, in __next__
    data = self._next_data()
  File "/home/aiotlab/anaconda3/envs/longvaipe/lib/python3.8/site-packages/torch/utils/data/dataloader.py", line 1203, in _next_data
    return self._process_data(data)
  File "/home/aiotlab/anaconda3/envs/longvaipe/lib/python3.8/site-packages/torch/utils/data/dataloader.py", line 1229, in _process_data
    data.reraise()
  File "/home/aiotlab/anaconda3/envs/longvaipe/lib/python3.8/site-packages/torch/_utils.py", line 434, in reraise
    raise exception
RuntimeError: Caught RuntimeError in DataLoader worker process 0.
Original Traceback (most recent call last):
  File "/home/aiotlab/anaconda3/envs/longvaipe/lib/python3.8/site-packages/torch/utils/data/_utils/worker.py", line 287, in _worker_loop
    data = fetcher.fetch(index)
  File "/home/aiotlab/anaconda3/envs/longvaipe/lib/python3.8/site-packages/torch/utils/data/_utils/fetch.py", line 52, in fetch
    return self.collate_fn(data)
  File "/home/aiotlab/anaconda3/envs/longvaipe/lib/python3.8/site-packages/torch/utils/data/_utils/collate.py", line 74, in default_collate
    return {key: default_collate([d[key] for d in batch]) for key in elem}
  File "/home/aiotlab/anaconda3/envs/longvaipe/lib/python3.8/site-packages/torch/utils/data/_utils/collate.py", line 74, in <dictcomp>
    return {key: default_collate([d[key] for d in batch]) for key in elem}
  File "/home/aiotlab/anaconda3/envs/longvaipe/lib/python3.8/site-packages/torch/utils/data/_utils/collate.py", line 54, in default_collate
    storage = elem.storage()._new_shared(numel)
  File "/home/aiotlab/anaconda3/envs/longvaipe/lib/python3.8/site-packages/torch/storage.py", line 157, in _new_shared
    return cls._new_using_fd(size)
RuntimeError: falseINTERNAL ASSERT FAILED at "/opt/conda/conda-bld/pytorch_1639180588308/work/aten/src/ATen/MapAllocator.cpp":263, please report a bug to PyTorch. unable to open shared memory object </torch_47137_0> in read-write mode